<sdf version='1.7'>
  <world name='default'>
    <light name='sun' type='directional'>
      <cast_shadows>1</cast_shadows>
      <pose>0 0 10 0 -0 0</pose>
      <diffuse>0.8 0.8 0.8 1</diffuse>
      <specular>0.2 0.2 0.2 1</specular>
      <attenuation>
        <range>1000</range>
        <constant>0.9</constant>
        <linear>0.01</linear>
        <quadratic>0.001</quadratic>
      </attenuation>
      <direction>-0.5 0.1 -0.9</direction>
      <spot>
        <inner_angle>0</inner_angle>
        <outer_angle>0</outer_angle>
        <falloff>0</falloff>
      </spot>
    </light>
    <model name='ground_plane'>
      <static>1</static>
      <link name='link'>
        <collision name='collision'>
          <geometry>
            <plane>
              <normal>0 0 1</normal>
              <size>100 100</size>
            </plane>
          </geometry>
          <surface>
            <contact>
              <collide_bitmask>65535</collide_bitmask>
              <ode/>
            </contact>
            <friction>
              <ode>
                <mu>100</mu>
                <mu2>50</mu2>
              </ode>
              <torsional>
                <ode/>
              </torsional>
            </friction>
            <bounce/>
          </surface>
          <max_contacts>10</max_contacts>
        </collision>
        <visual name='visual'>
          <cast_shadows>0</cast_shadows>
          <geometry>
            <plane>
              <normal>0 0 1</normal>
              <size>100 100</size>
            </plane>
          </geometry>
          <material>
            <script>
              <uri>file://media/materials/scripts/gazebo.material</uri>
              <name>Gazebo/Grey</name>
            </script>
          </material>
        </visual>
        <self_collide>0</self_collide>
        <enable_wind>0</enable_wind>
        <kinematic>0</kinematic>
      </link>
    </model>
    <gravity>0 0 -9.8</gravity>
    <magnetic_field>6e-06 2.3e-05 -4.2e-05</magnetic_field>
    <atmosphere type='adiabatic'/>
    <physics type='ode'>
      <max_step_size>0.001</max_step_size>
      <real_time_factor>1</real_time_factor>
      <real_time_update_rate>1000</real_time_update_rate>
    </physics>
    <scene>
      <ambient>0.4 0.4 0.4 1</ambient>
      <background>0.7 0.7 0.7 1</background>
      <shadows>1</shadows>
    </scene>
    <wind/>
    <spherical_coordinates>
      <surface_model>EARTH_WGS84</surface_model>
      <latitude_deg>0</latitude_deg>
      <longitude_deg>0</longitude_deg>
      <elevation>0</elevation>
      <heading_deg>0</heading_deg>
    </spherical_coordinates>
    <model name='Construction Barrel'>
      <link name='link'>
        <inertial>
          <pose>0 0 0.4 0 -0 0</pose>
          <mass>500</mass>
          <inertia>
            <ixx>51.2096</ixx>
            <iyy>51.2096</iyy>
            <izz>25</izz>
            <ixy>0</ixy>
            <ixz>0</ixz>
            <iyz>0</iyz>
          </inertia>
        </inertial>
        <collision name='collision'>
          <geometry>
            <mesh>
              <uri>model://construction_barrel/meshes/construction_barrel.dae</uri>
            </mesh>
          </geometry>
          <max_contacts>10</max_contacts>
          <surface>
            <contact>
              <ode/>
            </contact>
            <bounce/>
            <friction>
              <torsional>
                <ode/>
              </torsional>
              <ode/>
            </friction>
          </surface>
        </collision>
        <visual name='visual'>
          <geometry>
            <mesh>
              <uri>model://construction_barrel/meshes/construction_barrel.dae</uri>
            </mesh>
          </geometry>
        </visual>
        <self_collide>0</self_collide>
        <enable_wind>0</enable_wind>
        <kinematic>0</kinematic>
      </link>
      <pose>-0.782836 2.9196 0 0 -0 0</pose>
    </model>
    <model name='Construction Barrel_0'>
      <link name='link'>
        <inertial>
          <pose>0 0 0.4 0 -0 0</pose>
          <mass>500</mass>
          <inertia>
            <ixx>51.2096</ixx>
            <iyy>51.2096</iyy>
            <izz>25</izz>
            <ixy>0</ixy>
            <ixz>0</ixz>
            <iyz>0</iyz>
          </inertia>
        </inertial>
        <collision name='collision'>
          <geometry>
            <mesh>
              <uri>model://construction_barrel/meshes/construction_barrel.dae</uri>
            </mesh>
          </geometry>
          <max_contacts>10</max_contacts>
          <surface>
            <contact>
              <ode/>
            </contact>
            <bounce/>
            <friction>
              <torsional>
                <ode/>
              </torsional>
              <ode/>
            </friction>
          </surface>
        </collision>
        <visual name='visual'>
          <geometry>
            <mesh>
              <uri>model://construction_barrel/meshes/construction_barrel.dae</uri>
            </mesh>
          </geometry>
        </visual>
        <self_collide>0</self_collide>
        <enable_wind>0</enable_wind>
        <kinematic>0</kinematic>
      </link>
      <pose>3.18839 2.46495 0 0 -0 0</pose>
    </model>
    <model name='Construction Cone'>
      <link name='link'>
        <collision name='collision'>
          <geometry>
            <mesh>
              <scale>10 10 10</scale>
              <uri>model://construction_cone/meshes/construction_cone.dae</uri>
            </mesh>
          </geometry>
          <max_contacts>10</max_contacts>
          <surface>
            <contact>
              <ode/>
            </contact>
            <bounce/>
            <friction>
              <torsional>
                <ode/>
              </torsional>
              <ode/>
            </friction>
          </surface>
        </collision>
        <visual name='visual'>
          <geometry>
            <mesh>
              <scale>10 10 10</scale>
              <uri>model://construction_cone/meshes/construction_cone.dae</uri>
            </mesh>
          </geometry>
        </visual>
        <self_collide>0</self_collide>
        <inertial>
          <pose>0 0 0 0 -0 0</pose>
          <inertia>
            <ixx>1</ixx>
            <ixy>0</ixy>
            <ixz>0</ixz>
            <iyy>1</iyy>
            <iyz>0</iyz>
            <izz>1</izz>
          </inertia>
          <mass>1</mass>
        </inertial>
        <enable_wind>0</enable_wind>
        <kinematic>0</kinematic>
      </link>
      <pose>2.97412 0.891006 0 0 -0 0</pose>
    </model>
    <model name='Construction Cone_0'>
      <link name='link'>
        <collision name='collision'>
          <geometry>
            <mesh>
              <scale>10 10 10</scale>
              <uri>model://construction_cone/meshes/construction_cone.dae</uri>
            </mesh>
          </geometry>
          <max_contacts>10</max_contacts>
          <surface>
            <contact>
              <ode/>
            </contact>
            <bounce/>
            <friction>
              <torsional>
                <ode/>
              </torsional>
              <ode/>
            </friction>
          </surface>
        </collision>
        <visual name='visual'>
          <geometry>
            <mesh>
              <scale>10 10 10</scale>
              <uri>model://construction_cone/meshes/construction_cone.dae</uri>
            </mesh>
          </geometry>
        </visual>
        <self_collide>0</self_collide>
        <inertial>
          <pose>0 0 0 0 -0 0</pose>
          <inertia>
            <ixx>1</ixx>
            <ixy>0</ixy>
            <ixz>0</ixz>
            <iyy>1</iyy>
            <iyz>0</iyz>
            <izz>1</izz>
          </inertia>
          <mass>1</mass>
        </inertial>
        <enable_wind>0</enable_wind>
        <kinematic>0</kinematic>
      </link>
      <pose>3.38752 -1.43412 0 0 -0 0</pose>
    </model>
    <model name='Construction Cone_1'>
      <link name='link'>
        <collision name='collision'>
          <geometry>
            <mesh>
              <scale>10 10 10</scale>
              <uri>model://construction_cone/meshes/construction_cone.dae</uri>
            </mesh>
          </geometry>
          <max_contacts>10</max_contacts>
          <surface>
            <contact>
              <ode/>
            </contact>
            <bounce/>
            <friction>
              <torsional>
                <ode/>
              </torsional>
              <ode/>
            </friction>
          </surface>
        </collision>
        <visual name='visual'>
          <geometry>
            <mesh>
              <scale>10 10 10</scale>
              <uri>model://construction_cone/meshes/construction_cone.dae</uri>
            </mesh>
          </geometry>
        </visual>
        <self_collide>0</self_collide>
        <inertial>
          <pose>0 0 0 0 -0 0</pose>
          <inertia>
            <ixx>1</ixx>
            <ixy>0</ixy>
            <ixz>0</ixz>
            <iyy>1</iyy>
            <iyz>0</iyz>
            <izz>1</izz>
          </inertia>
          <mass>1</mass>
        </inertial>
        <enable_wind>0</enable_wind>
        <kinematic>0</kinematic>
      </link>
      <pose>-4.63739 -3.10195 0 0 -0 0</pose>
    </model>
    <model name='Construction Barrel_1'>
      <link name='link'>
        <inertial>
          <pose>0 0 0.4 0 -0 0</pose>
          <mass>500</mass>
          <inertia>
            <ixx>51.2096</ixx>
            <iyy>51.2096</iyy>
            <izz>25</izz>
            <ixy>0</ixy>
            <ixz>0</ixz>
            <iyz>0</iyz>
          </inertia>
        </inertial>
        <collision name='collision'>
          <geometry>
            <mesh>
              <uri>model://construction_barrel/meshes/construction_barrel.dae</uri>
            </mesh>
          </geometry>
          <max_contacts>10</max_contacts>
          <surface>
            <contact>
              <ode/>
            </contact>
            <bounce/>
            <friction>
              <torsional>
                <ode/>
              </torsional>
              <ode/>
            </friction>
          </surface>
        </collision>
        <visual name='visual'>
          <geometry>
            <mesh>
              <uri>model://construction_barrel/meshes/construction_barrel.dae</uri>
            </mesh>
          </geometry>
        </visual>
        <self_collide>0</self_collide>
        <enable_wind>0</enable_wind>
        <kinematic>0</kinematic>
      </link>
      <pose>-7.79781 1.12773 0 0 -0 0</pose>
    </model>
    <model name='Construction Barrel_2'>
      <link name='link'>
        <inertial>
          <pose>0 0 0.4 0 -0 0</pose>
          <mass>500</mass>
          <inertia>
            <ixx>51.2096</ixx>
            <iyy>51.2096</iyy>
            <izz>25</izz>
            <ixy>0</ixy>
            <ixz>0</ixz>
            <iyz>0</iyz>
          </inertia>
        </inertial>
        <collision name='collision'>
          <geometry>
            <mesh>
              <uri>model://construction_barrel/meshes/construction_barrel.dae</uri>
            </mesh>
          </geometry>
          <max_contacts>10</max_contacts>
          <surface>
            <contact>
              <ode/>
            </contact>
            <bounce/>
            <friction>
              <torsional>
                <ode/>
              </torsional>
              <ode/>
            </friction>
          </surface>
        </collision>
        <visual name='visual'>
          <geometry>
            <mesh>
              <uri>model://construction_barrel/meshes/construction_barrel.dae</uri>
            </mesh>
          </geometry>
        </visual>
        <self_collide>0</self_collide>
        <enable_wind>0</enable_wind>
        <kinematic>0</kinematic>
      </link>
      <pose>-4.42737 -0.645032 0 0 -0 0</pose>
    </model>
    <model name='cube_20k'>
      <link name='link'>
        <pose>0 0 0.5 0 -0 0</pose>
        <collision name='collision'>
          <geometry>
            <mesh>
              <uri>model://cube_20k/meshes/cube_20k.stl</uri>
              <scale>0.5 0.5 0.5</scale>
            </mesh>
          </geometry>
          <max_contacts>10</max_contacts>
          <surface>
            <contact>
              <ode/>
            </contact>
            <bounce/>
            <friction>
              <torsional>
                <ode/>
              </torsional>
              <ode/>
            </friction>
          </surface>
        </collision>
        <visual name='visual'>
          <geometry>
            <mesh>
              <uri>model://cube_20k/meshes/cube_20k.stl</uri>
              <scale>0.5 0.5 0.5</scale>
            </mesh>
          </geometry>
        </visual>
        <self_collide>0</self_collide>
        <inertial>
          <pose>0 0 0 0 -0 0</pose>
          <inertia>
            <ixx>1</ixx>
            <ixy>0</ixy>
            <ixz>0</ixz>
            <iyy>1</iyy>
            <iyz>0</iyz>
            <izz>1</izz>
          </inertia>
          <mass>1</mass>
        </inertial>
        <enable_wind>0</enable_wind>
        <kinematic>0</kinematic>
      </link>
      <pose>-1.02044 -3.96403 0 0 -0 0</pose>
    </model>
    <model name='demo_joint_friction'>
      <pose>0.742401 -2.41255 0.06 0 -0 0</pose>
      <link name='link_base'>
        <inertial>
          <mass>100</mass>
          <inertia>
            <ixx>1.2</ixx>
            <ixy>0</ixy>
            <ixz>0</ixz>
            <iyy>3.64</iyy>
            <iyz>0</iyz>
            <izz>4.6</izz>
          </inertia>
          <pose>0 0 0 0 -0 0</pose>
        </inertial>
        <gravity>1</gravity>
        <self_collide>0</self_collide>
        <kinematic>0</kinematic>
        <enable_wind>0</enable_wind>
        <visual name='visual_base'>
          <geometry>
            <mesh>
              <uri>model://demo_joint_friction/meshes/base_model.dae</uri>
              <scale>0.001 0.001 0.001</scale>
            </mesh>
          </geometry>
          <cast_shadows>1</cast_shadows>
        </visual>
        <collision name='collision_base'>
          <geometry>
            <box>
              <size>0.65 0.36 0.12</size>
            </box>
          </geometry>
          <max_contacts>10</max_contacts>
          <surface>
            <contact>
              <ode/>
            </contact>
            <bounce/>
            <friction>
              <torsional>
                <ode/>
              </torsional>
              <ode/>
            </friction>
          </surface>
        </collision>
      </link>
      <link name='link_high_friction'>
        <gravity>0</gravity>
        <pose>0.12 0 0.15 0.785398 -0 0</pose>
        <inertial>
          <pose>0 0 0.12 0 -0 0</pose>
          <mass>1</mass>
          <inertia>
            <ixx>0.0051</ixx>
            <ixy>0</ixy>
            <ixz>0</ixz>
            <iyy>0.0051</iyy>
            <iyz>0</iyz>
            <izz>0.0006</izz>
          </inertia>
        </inertial>
        <visual name='visual_high_friction'>
          <pose>0 0 -0.15 0 -0 0</pose>
          <geometry>
            <mesh>
              <uri>model://demo_joint_friction/meshes/arm.stl</uri>
              <scale>0.001 0.001 0.001</scale>
            </mesh>
          </geometry>
          <material>
            <lighting>1</lighting>
            <script>
              <uri>file://media/materials/scripts/gazebo.material</uri>
              <name>Gazebo/Orange</name>
            </script>
          </material>
          <cast_shadows>1</cast_shadows>
        </visual>
        <self_collide>0</self_collide>
        <enable_wind>0</enable_wind>
        <kinematic>0</kinematic>
      </link>
      <joint name='joint_high_friction' type='revolute'>
        <parent>link_base</parent>
        <child>link_high_friction</child>
        <pose>0 0 0 -0.15 0 0</pose>
        <axis>
          <xyz>1 0 0</xyz>
          <dynamics>
            <damping>0</damping>
            <friction>2</friction>
            <spring_reference>-0.785398</spring_reference>
            <spring_stiffness>7</spring_stiffness>
          </dynamics>
          <limit>
            <lower>-1e+16</lower>
            <upper>1e+16</upper>
          </limit>
        </axis>
      </joint>
      <link name='link_medium_friction'>
        <gravity>0</gravity>
        <pose>0 0 0.15 0.785398 -0 0</pose>
        <inertial>
          <pose>0 0 0.12 0 -0 0</pose>
          <mass>1</mass>
          <inertia>
            <ixx>0.0051</ixx>
            <ixy>0</ixy>
            <ixz>0</ixz>
            <iyy>0.0051</iyy>
            <iyz>0</iyz>
            <izz>0.0006</izz>
          </inertia>
        </inertial>
        <visual name='visual_medium_friction'>
          <pose>0 0 -0.15 0 -0 0</pose>
          <geometry>
            <mesh>
              <uri>model://demo_joint_friction/meshes/arm.stl</uri>
              <scale>0.001 0.001 0.001</scale>
            </mesh>
          </geometry>
          <material>
            <lighting>1</lighting>
            <script>
              <uri>file://media/materials/scripts/gazebo.material</uri>
              <name>Gazebo/Orange</name>
            </script>
          </material>
          <cast_shadows>1</cast_shadows>
        </visual>
        <self_collide>0</self_collide>
        <enable_wind>0</enable_wind>
        <kinematic>0</kinematic>
      </link>
      <joint name='joint_medium_friction' type='revolute'>
        <parent>link_base</parent>
        <child>link_medium_friction</child>
        <pose>0 0 0 -0.15 0 0</pose>
        <axis>
          <xyz>1 0 0</xyz>
          <dynamics>
            <damping>0</damping>
            <friction>0.5</friction>
            <spring_reference>-0.785398</spring_reference>
            <spring_stiffness>7</spring_stiffness>
          </dynamics>
          <limit>
            <lower>-1e+16</lower>
            <upper>1e+16</upper>
          </limit>
        </axis>
      </joint>
      <link name='link_low_friction'>
        <gravity>0</gravity>
        <pose>-0.12 0 0.15 0.785398 -0 0</pose>
        <inertial>
          <pose>0 0 0.12 0 -0 0</pose>
          <mass>1</mass>
          <inertia>
            <ixx>0.0051</ixx>
            <ixy>0</ixy>
            <ixz>0</ixz>
            <iyy>0.0051</iyy>
            <iyz>0</iyz>
            <izz>0.0006</izz>
          </inertia>
        </inertial>
        <visual name='visual_low_friction'>
          <pose>0 0 -0.15 0 -0 0</pose>
          <geometry>
            <mesh>
              <uri>model://demo_joint_friction/meshes/arm.stl</uri>
              <scale>0.001 0.001 0.001</scale>
            </mesh>
          </geometry>
          <material>
            <lighting>1</lighting>
            <script>
              <uri>file://media/materials/scripts/gazebo.material</uri>
              <name>Gazebo/Orange</name>
            </script>
          </material>
          <cast_shadows>1</cast_shadows>
        </visual>
        <self_collide>0</self_collide>
        <enable_wind>0</enable_wind>
        <kinematic>0</kinematic>
      </link>
      <joint name='joint_low_friction' type='revolute'>
        <parent>link_base</parent>
        <child>link_low_friction</child>
        <pose>0 0 0 -0.15 0 0</pose>
        <axis>
          <xyz>1 0 0</xyz>
          <dynamics>
            <damping>0</damping>
            <friction>0.1</friction>
            <spring_reference>-0.785398</spring_reference>
            <spring_stiffness>7</spring_stiffness>
          </dynamics>
          <limit>
            <lower>-1e+16</lower>
            <upper>1e+16</upper>
          </limit>
        </axis>
      </joint>
      <allow_auto_disable>1</allow_auto_disable>
    </model>
    <model name='Construction Cone_2'>
      <link name='link'>
        <collision name='collision'>
          <geometry>
            <mesh>
              <scale>10 10 10</scale>
              <uri>model://construction_cone/meshes/construction_cone.dae</uri>
            </mesh>
          </geometry>
          <max_contacts>10</max_contacts>
          <surface>
            <contact>
              <ode/>
            </contact>
            <bounce/>
            <friction>
              <torsional>
                <ode/>
              </torsional>
              <ode/>
            </friction>
          </surface>
        </collision>
        <visual name='visual'>
          <geometry>
            <mesh>
              <scale>10 10 10</scale>
              <uri>model://construction_cone/meshes/construction_cone.dae</uri>
            </mesh>
          </geometry>
        </visual>
        <self_collide>0</self_collide>
        <inertial>
          <pose>0 0 0 0 -0 0</pose>
          <inertia>
            <ixx>1</ixx>
            <ixy>0</ixy>
            <ixz>0</ixz>
            <iyy>1</iyy>
            <iyz>0</iyz>
            <izz>1</izz>
          </inertia>
          <mass>1</mass>
        </inertial>
        <enable_wind>0</enable_wind>
        <kinematic>0</kinematic>
      </link>
      <pose>-2.68423 -1.15563 0 0 -0 0</pose>
    </model>
    <model name='Construction Barrel_3'>
      <link name='link'>
        <inertial>
          <pose>0 0 0.4 0 -0 0</pose>
          <mass>500</mass>
          <inertia>
            <ixx>51.2096</ixx>
            <iyy>51.2096</iyy>
            <izz>25</izz>
            <ixy>0</ixy>
            <ixz>0</ixz>
            <iyz>0</iyz>
          </inertia>
        </inertial>
        <collision name='collision'>
          <geometry>
            <mesh>
              <uri>model://construction_barrel/meshes/construction_barrel.dae</uri>
            </mesh>
          </geometry>
          <max_contacts>10</max_contacts>
          <surface>
            <contact>
              <ode/>
            </contact>
            <bounce/>
            <friction>
              <torsional>
                <ode/>
              </torsional>
              <ode/>
            </friction>
          </surface>
        </collision>
        <visual name='visual'>
          <geometry>
            <mesh>
              <uri>model://construction_barrel/meshes/construction_barrel.dae</uri>
            </mesh>
          </geometry>
        </visual>
        <self_collide>0</self_collide>
        <enable_wind>0</enable_wind>
        <kinematic>0</kinematic>
      </link>
      <pose>-0.236113 5.86921 0 0 -0 0</pose>
    </model>
    <model name='cube_20k_0'>
      <link name='link'>
        <pose>0 0 0.5 0 -0 0</pose>
        <collision name='collision'>
          <geometry>
            <mesh>
              <uri>model://cube_20k/meshes/cube_20k.stl</uri>
              <scale>0.5 0.5 0.5</scale>
            </mesh>
          </geometry>
          <max_contacts>10</max_contacts>
          <surface>
            <contact>
              <ode/>
            </contact>
            <bounce/>
            <friction>
              <torsional>
                <ode/>
              </torsional>
              <ode/>
            </friction>
          </surface>
        </collision>
        <visual name='visual'>
          <geometry>
            <mesh>
              <uri>model://cube_20k/meshes/cube_20k.stl</uri>
              <scale>0.5 0.5 0.5</scale>
            </mesh>
          </geometry>
        </visual>
        <self_collide>0</self_collide>
        <inertial>
          <pose>0 0 0 0 -0 0</pose>
          <inertia>
            <ixx>1</ixx>
            <ixy>0</ixy>
            <ixz>0</ixz>
            <iyy>1</iyy>
            <iyz>0</iyz>
            <izz>1</izz>
          </inertia>
          <mass>1</mass>
        </inertial>
        <enable_wind>0</enable_wind>
        <kinematic>0</kinematic>
      </link>
      <pose>0.947482 7.33524 0 0 -0 0</pose>
    </model>
    <model name='demo_joint_friction_0'>
      <pose>4.81485 4.09137 0.06 0 -0 0</pose>
      <link name='link_base'>
        <inertial>
          <mass>100</mass>
          <inertia>
            <ixx>1.2</ixx>
            <ixy>0</ixy>
            <ixz>0</ixz>
            <iyy>3.64</iyy>
            <iyz>0</iyz>
            <izz>4.6</izz>
          </inertia>
          <pose>0 0 0 0 -0 0</pose>
        </inertial>
        <gravity>1</gravity>
        <self_collide>0</self_collide>
        <kinematic>0</kinematic>
        <enable_wind>0</enable_wind>
        <visual name='visual_base'>
          <geometry>
            <mesh>
              <uri>model://demo_joint_friction/meshes/base_model.dae</uri>
              <scale>0.001 0.001 0.001</scale>
            </mesh>
          </geometry>
          <cast_shadows>1</cast_shadows>
        </visual>
        <collision name='collision_base'>
          <geometry>
            <box>
              <size>0.65 0.36 0.12</size>
            </box>
          </geometry>
          <max_contacts>10</max_contacts>
          <surface>
            <contact>
              <ode/>
            </contact>
            <bounce/>
            <friction>
              <torsional>
                <ode/>
              </torsional>
              <ode/>
            </friction>
          </surface>
        </collision>
      </link>
      <link name='link_high_friction'>
        <gravity>0</gravity>
        <pose>0.12 0 0.15 0.785398 -0 0</pose>
        <inertial>
          <pose>0 0 0.12 0 -0 0</pose>
          <mass>1</mass>
          <inertia>
            <ixx>0.0051</ixx>
            <ixy>0</ixy>
            <ixz>0</ixz>
            <iyy>0.0051</iyy>
            <iyz>0</iyz>
            <izz>0.0006</izz>
          </inertia>
        </inertial>
        <visual name='visual_high_friction'>
          <pose>0 0 -0.15 0 -0 0</pose>
          <geometry>
            <mesh>
              <uri>model://demo_joint_friction/meshes/arm.stl</uri>
              <scale>0.001 0.001 0.001</scale>
            </mesh>
          </geometry>
          <material>
            <lighting>1</lighting>
            <script>
              <uri>file://media/materials/scripts/gazebo.material</uri>
              <name>Gazebo/Orange</name>
            </script>
          </material>
          <cast_shadows>1</cast_shadows>
        </visual>
        <self_collide>0</self_collide>
        <enable_wind>0</enable_wind>
        <kinematic>0</kinematic>
      </link>
      <joint name='joint_high_friction' type='revolute'>
        <parent>link_base</parent>
        <child>link_high_friction</child>
        <pose>0 0 0 -0.15 0 0</pose>
        <axis>
          <xyz>1 0 0</xyz>
          <dynamics>
            <damping>0</damping>
            <friction>2</friction>
            <spring_reference>-0.785398</spring_reference>
            <spring_stiffness>7</spring_stiffness>
          </dynamics>
          <limit>
            <lower>-1e+16</lower>
            <upper>1e+16</upper>
          </limit>
        </axis>
      </joint>
      <link name='link_medium_friction'>
        <gravity>0</gravity>
        <pose>0 0 0.15 0.785398 -0 0</pose>
        <inertial>
          <pose>0 0 0.12 0 -0 0</pose>
          <mass>1</mass>
          <inertia>
            <ixx>0.0051</ixx>
            <ixy>0</ixy>
            <ixz>0</ixz>
            <iyy>0.0051</iyy>
            <iyz>0</iyz>
            <izz>0.0006</izz>
          </inertia>
        </inertial>
        <visual name='visual_medium_friction'>
          <pose>0 0 -0.15 0 -0 0</pose>
          <geometry>
            <mesh>
              <uri>model://demo_joint_friction/meshes/arm.stl</uri>
              <scale>0.001 0.001 0.001</scale>
            </mesh>
          </geometry>
          <material>
            <lighting>1</lighting>
            <script>
              <uri>file://media/materials/scripts/gazebo.material</uri>
              <name>Gazebo/Orange</name>
            </script>
          </material>
          <cast_shadows>1</cast_shadows>
        </visual>
        <self_collide>0</self_collide>
        <enable_wind>0</enable_wind>
        <kinematic>0</kinematic>
      </link>
      <joint name='joint_medium_friction' type='revolute'>
        <parent>link_base</parent>
        <child>link_medium_friction</child>
        <pose>0 0 0 -0.15 0 0</pose>
        <axis>
          <xyz>1 0 0</xyz>
          <dynamics>
            <damping>0</damping>
            <friction>0.5</friction>
            <spring_reference>-0.785398</spring_reference>
            <spring_stiffness>7</spring_stiffness>
          </dynamics>
          <limit>
            <lower>-1e+16</lower>
            <upper>1e+16</upper>
          </limit>
        </axis>
      </joint>
      <link name='link_low_friction'>
        <gravity>0</gravity>
        <pose>-0.12 0 0.15 0.785398 -0 0</pose>
        <inertial>
          <pose>0 0 0.12 0 -0 0</pose>
          <mass>1</mass>
          <inertia>
            <ixx>0.0051</ixx>
            <ixy>0</ixy>
            <ixz>0</ixz>
            <iyy>0.0051</iyy>
            <iyz>0</iyz>
            <izz>0.0006</izz>
          </inertia>
        </inertial>
        <visual name='visual_low_friction'>
          <pose>0 0 -0.15 0 -0 0</pose>
          <geometry>
            <mesh>
              <uri>model://demo_joint_friction/meshes/arm.stl</uri>
              <scale>0.001 0.001 0.001</scale>
            </mesh>
          </geometry>
          <material>
            <lighting>1</lighting>
            <script>
              <uri>file://media/materials/scripts/gazebo.material</uri>
              <name>Gazebo/Orange</name>
            </script>
          </material>
          <cast_shadows>1</cast_shadows>
        </visual>
        <self_collide>0</self_collide>
        <enable_wind>0</enable_wind>
        <kinematic>0</kinematic>
      </link>
      <joint name='joint_low_friction' type='revolute'>
        <parent>link_base</parent>
        <child>link_low_friction</child>
        <pose>0 0 0 -0.15 0 0</pose>
        <axis>
          <xyz>1 0 0</xyz>
          <dynamics>
            <damping>0</damping>
            <friction>0.1</friction>
            <spring_reference>-0.785398</spring_reference>
            <spring_stiffness>7</spring_stiffness>
          </dynamics>
          <limit>
            <lower>-1e+16</lower>
            <upper>1e+16</upper>
          </limit>
        </axis>
      </joint>
      <allow_auto_disable>1</allow_auto_disable>
    </model>
    <state world_name='default'>
      <sim_time>567 819000000</sim_time>
      <real_time>568 788869750</real_time>
      <wall_time>1718184914 816947480</wall_time>
      <iterations>567819</iterations>
      <model name='Construction Barrel'>
        <pose>-0.782923 2.91958 -0 0 -0 -2.7e-05</pose>
        <scale>1 1 1</scale>
        <link name='link'>
          <pose>-0.782923 2.91958 -0 0 -0 -2.7e-05</pose>
          <velocity>0 0 0 0 -0 0</velocity>
          <acceleration>-0.578365 -0.988908 -0.730232 2.47227 -1.44591 0</acceleration>
          <wrench>-289.182 -494.454 -365.116 0 -0 0</wrench>
        </link>
      </model>
      <model name='Construction Barrel_0'>
        <pose>3.18831 2.46492 -0 0 -0 -2.2e-05</pose>
        <scale>1 1 1</scale>
        <link name='link'>
          <pose>3.18831 2.46492 -0 0 -0 -2.2e-05</pose>
          <velocity>0 0 0 0 -0 0</velocity>
          <acceleration>-3.87344 -0.446095 -0.496378 -2.02768 0.258692 3.1404</acceleration>
          <wrench>-1936.72 -223.047 -248.189 0 -0 0</wrench>
        </link>
      </model>
      <model name='Construction Barrel_1'>
        <pose>-7.79788 1.12771 -1e-06 3e-06 1e-05 -1.8e-05</pose>
        <scale>1 1 1</scale>
        <link name='link'>
          <pose>-7.79788 1.12771 -1e-06 3e-06 1e-05 -1.8e-05</pose>
          <velocity>0 0 0 0 -0 0</velocity>
          <acceleration>2.39724 4.10941 -3.69296 2.28363 -0.442189 0.216966</acceleration>
          <wrench>1198.62 2054.7 -1846.48 0 -0 0</wrench>
        </link>
      </model>
      <model name='Construction Barrel_2'>
        <pose>-4.42743 -0.645052 0 0 0 -1.5e-05</pose>
        <scale>1 1 1</scale>
        <link name='link'>
          <pose>-4.42743 -0.645052 0 0 0 -1.5e-05</pose>
          <velocity>0 0 0 0 -0 0</velocity>
          <acceleration>3.45861 5.74433 4.40608 1.34635 0.778869 3.14097</acceleration>
          <wrench>1729.3 2872.16 2203.04 0 -0 0</wrench>
        </link>
      </model>
      <model name='Construction Barrel_3'>
        <pose>-0.236147 5.8692 0 1e-06 1e-06 -9e-06</pose>
        <scale>1 1 1</scale>
        <link name='link'>
          <pose>-0.236147 5.8692 0 1e-06 1e-06 -9e-06</pose>
          <velocity>0 0 0 0 -0 0</velocity>
          <acceleration>-0.447747 4.86284 0.318841 0.406505 -1.12792 0.008323</acceleration>
          <wrench>-223.873 2431.42 159.42 0 -0 0</wrench>
        </link>
      </model>
      <model name='Construction Cone'>
        <pose>2.97958 0.972789 -0 0 -1e-06 -0.025435</pose>
        <scale>1 1 1</scale>
        <link name='link'>
          <pose>2.97958 0.972789 -0 0 -1e-06 -0.025435</pose>
          <velocity>0 0 0 0 -0 0</velocity>
          <acceleration>-0 0 0.008512 2.53504 -1.1516 -3.14159</acceleration>
          <wrench>-0 0 0.008512 0 -0 0</wrench>
        </link>
      </model>
      <model name='Construction Cone_0'>
        <pose>3.38752 -1.43412 -0 0 -0 0</pose>
        <scale>1 1 1</scale>
        <link name='link'>
          <pose>3.38752 -1.43412 -0 0 -0 0</pose>
          <velocity>0 0 0 0 -0 0</velocity>
          <acceleration>-1e-06 -1e-06 7.6758 -3.10128 -1.28746 -2e-06</acceleration>
          <wrench>-1e-06 -1e-06 7.6758 0 -0 0</wrench>
        </link>
      </model>
      <model name='Construction Cone_1'>
        <pose>-4.63739 -3.10195 -8e-06 -4e-06 1e-06 0</pose>
        <scale>1 1 1</scale>
        <link name='link'>
          <pose>-4.63739 -3.10195 -8e-06 -4e-06 1e-06 0</pose>
          <velocity>0 0 0 0 -0 0</velocity>
          <acceleration>0 0 -9.8 -0 -0 -0</acceleration>
          <wrench>0 0 -9.8 0 -0 0</wrench>
        </link>
      </model>
      <model name='Construction Cone_2'>
        <pose>-2.68423 -1.15563 -0 0 -0 0</pose>
        <scale>1 1 1</scale>
        <link name='link'>
          <pose>-2.68423 -1.15563 -0 0 -0 0</pose>
          <velocity>0 0 0 0 -0 0</velocity>
          <acceleration>0 -0 -0.008512 -2.58585 1.13682 3.14159</acceleration>
          <wrench>0 -0 -0.008512 0 -0 0</wrench>
        </link>
      </model>
      <model name='cube_20k'>
        <pose>-1.02044 -3.96403 -0 0 1e-06 -1.5e-05</pose>
        <scale>1 1 1</scale>
        <link name='link'>
          <pose>-1.02044 -3.96403 0.5 0 1e-06 -1.5e-05</pose>
          <velocity>0 0 0 0 -0 0</velocity>
          <acceleration>1.07556 0.034258 -0.19878 3.07097 0.991637 3.13739</acceleration>
          <wrench>1.07556 0.034258 -0.19878 0 -0 0</wrench>
        </link>
      </model>
      <model name='cube_20k_0'>
        <pose>0.947483 7.33524 -0 -0 1e-06 -7e-06</pose>
        <scale>1 1 1</scale>
        <link name='link'>
          <pose>0.947483 7.33524 0.5 -0 1e-06 -7e-06</pose>
          <velocity>0 0 0 0 -0 0</velocity>
          <acceleration>1.07556 0.034266 -0.19878 3.07096 0.991637 3.13739</acceleration>
          <wrench>1.07556 0.034266 -0.19878 0 -0 0</wrench>
        </link>
      </model>
      <model name='demo_joint_friction'>
        <pose>0.742401 -2.41255 0.06 0 -0 0</pose>
        <scale>1 1 1</scale>
        <link name='link_base'>
          <pose>0.742401 -2.41255 0.06 0 -0 0</pose>
          <velocity>-0 -0 0 0 -0 0</velocity>
          <acceleration>-0 -0 0 0 -0 0</acceleration>
          <wrench>-0 -0 0 0 -0 0</wrench>
        </link>
        <link name='link_high_friction'>
          <pose>0.862401 -2.41255 0.21 -0.213956 0 0</pose>
          <velocity>-0 -0 0 -0 -0 -0</velocity>
          <acceleration>-0 -0 0 -0 -0 -0</acceleration>
          <wrench>-0 -0 0 0 -0 0</wrench>
        </link>
        <link name='link_low_friction'>
          <pose>0.622401 -2.41255 0.21 -0.013303 0 0</pose>
          <velocity>-0 -0 0 0 -0 0</velocity>
          <acceleration>-0 -0 -0 0 -0 0</acceleration>
          <wrench>-0 -0 -0 0 -0 0</wrench>
        </link>
        <link name='link_medium_friction'>
          <pose>0.742401 -2.41255 0.21 -0.071026 0 0</pose>
          <velocity>-0 -0 0 0 -0 0</velocity>
          <acceleration>-0 -0 0 0 -0 0</acceleration>
          <wrench>-0 -0 0 0 -0 0</wrench>
        </link>
      </model>
      <model name='demo_joint_friction_0'>
        <pose>4.81485 4.09137 0.06 0 -0 0</pose>
        <scale>1 1 1</scale>
        <link name='link_base'>
          <pose>4.81485 4.09137 0.06 0 -0 0</pose>
          <velocity>0 0 0 0 -0 0</velocity>
          <acceleration>0 -0 0 0 -0 0</acceleration>
          <wrench>0 -0 0 0 -0 0</wrench>
        </link>
        <link name='link_high_friction'>
          <pose>4.93485 4.09137 0.21 -0.213956 0 0</pose>
          <velocity>0 0 0 0 -0 0</velocity>
          <acceleration>0 -0 0 0 -0 0</acceleration>
          <wrench>0 -0 0 0 -0 0</wrench>
        </link>
        <link name='link_low_friction'>
          <pose>4.69485 4.09137 0.21 -0.013303 0 0</pose>
          <velocity>0 0 0 0 -0 0</velocity>
          <acceleration>0 -0 0 0 -0 0</acceleration>
          <wrench>0 -0 0 0 -0 0</wrench>
        </link>
        <link name='link_medium_friction'>
          <pose>4.81485 4.09137 0.21 -0.071026 0 0</pose>
          <velocity>0 0 0 0 -0 0</velocity>
          <acceleration>0 -0 0 0 -0 0</acceleration>
          <wrench>0 -0 0 0 -0 0</wrench>
        </link>
      </model>
      <model name='ground_plane'>
        <pose>0 0 0 0 -0 0</pose>
        <scale>1 1 1</scale>
        <link name='link'>
          <pose>0 0 0 0 -0 0</pose>
          <velocity>0 0 0 0 -0 0</velocity>
          <acceleration>0 0 0 0 -0 0</acceleration>
          <wrench>0 0 0 0 -0 0</wrench>
        </link>
      </model>
      <light name='sun'>
        <pose>0 0 10 0 -0 0</pose>
      </light>
    </state>
    <gui fullscreen='0'>
      <camera name='user_camera'>
        <pose>9.48212 -3.27764 13.4931 -0 0.919643 2.54019</pose>
        <view_controller>orbit</view_controller>
        <projection_type>perspective</projection_type>
      </camera>
    </gui>
  </world>
</sdf>
